{
 "cells": [
  {
   "cell_type": "markdown",
   "metadata": {},
   "source": [
    "# Pixeltable Media Processing Demo\n",
    "\n",
    "This notebook demonstrates how to use the ImageProcessor and VideoProcessor classes to process and search media content."
   ]
  },
  {
   "cell_type": "code",
   "execution_count": 1,
   "metadata": {},
   "outputs": [
    {
     "name": "stdout",
     "output_type": "stream",
     "text": [
      "Directorio de archivos: c:\\Dev\\PPS\\Pixeltable\n"
     ]
    }
   ],
   "source": [
    "import os\n",
    "import sys\n",
    "from image_video_processor import ImageProcessor, VideoProcessor\n",
    "import PIL.Image\n",
    "import glob\n",
    "\n",
    "current_path = os.getcwd()\n",
    "print(f\"Directorio de archivos: {current_path}\")"
   ]
  },
  {
   "cell_type": "markdown",
   "metadata": {},
   "source": [
    "## Configuración\n",
    "\n",
    "Directorios para las imágenes y videos. Así como query para búsqueda de imágenes por texto y por similaridad de imagen."
   ]
  },
  {
   "cell_type": "code",
   "execution_count": 2,
   "metadata": {},
   "outputs": [
    {
     "name": "stdout",
     "output_type": "stream",
     "text": [
      "Encontradas 12241 imágenes en el directorio ../Media/Images/cars/\n",
      " - 1478899619711375757.jpg\n",
      " - 1478899620284123429.jpg\n",
      " - 1478899620853487177.jpg\n",
      " - 1478899621425948164.jpg\n",
      " - 1478899621996269312.jpg\n",
      " ... and 12236 more\n",
      "Procesamiento hecho\n"
     ]
    }
   ],
   "source": [
    "# Parámetros\n",
    "images_directory = \"../Media/Images/cars/\"\n",
    "videos_directory = \"../Media/Videos/\"\n",
    "search_query = \"car\"  # Query to search for in videos\n",
    "search_image_path = \"Media/Images/cars/1478020796209432542.jpg\"  # Query image\n",
    "\n",
    "\n",
    "# Validaciones\n",
    "if not os.path.exists(images_directory):\n",
    "    print(f\"Warning: Directorio de imágenes {images_directory} no encontrado. Creándolo.\")\n",
    "    os.makedirs(images_directory, exist_ok=True)\n",
    "    \n",
    "if not os.path.exists(videos_directory):\n",
    "    print(f\"Warning: Directorio de vidoes {videos_directory} no encontrado. Creaándolo.\")\n",
    "    os.makedirs(videos_directory, exist_ok=True)\n",
    "\n",
    "# Lista de imágenes\n",
    "image_files = glob.glob(os.path.join(images_directory, \"*.*\"))\n",
    "print(f\"Encontradas {len(image_files)} imágenes en el directorio {images_directory}\")\n",
    "for img in image_files[:5]:  # Muestra los 5 primeros\n",
    "    print(f\" - {os.path.basename(img)}\")\n",
    "if len(image_files) > 5:\n",
    "    print(f\" ... and {len(image_files) - 5} more\")\n",
    "    \n",
    "print(\"Procesamiento hecho\")"
   ]
  },
  {
   "cell_type": "code",
   "execution_count": 3,
   "metadata": {},
   "outputs": [
    {
     "name": "stderr",
     "output_type": "stream",
     "text": [
      "Timeout starting server.\n",
      "Showing contents of postgres server log (C:\\Users\\mateo\\.pixeltable\\pgdata\\log) below:\n",
      "2025-03-29 14:44:29.554 -03 [16376] LOG:  starting PostgreSQL 16.8 on x86_64-pc-mingw64, compiled by gcc.exe (x86_64-posix-seh-rev2, Built by MinGW-W64 project) 12.2.0, 64-bit\n",
      "2025-03-29 14:44:29.556 -03 [16376] LOG:  listening on IPv4 address \"127.0.0.1\", port 57822\n",
      "2025-03-29 14:44:29.586 -03 [7548] LOG:  database system was shut down at 2025-03-29 14:44:24 -03\n",
      "2025-03-29 14:44:29.600 -03 [16376] LOG:  database system is ready to accept connections\n",
      "2025-03-29 14:45:04.383 -03 [24244] LOG:  invalid length of startup packet\n",
      "2025-03-29 14:45:04.401 -03 [24992] LOG:  invalid length of startup packet\n",
      "2025-03-29 14:45:04.418 -03 [17800] LOG:  invalid length of startup packet\n",
      "2025-03-29 14:45:04.435 -03 [29628] LOG:  invalid length of startup packet\n",
      "2025-03-29 14:45:04.451 -03 [11712] LOG:  invalid length of startup packet\n",
      "2025-03-29 14:45:04.467 -03 [24876] LOG:  invalid length of startup packet\n",
      "2025-03-29 14:45:04.487 -03 [13464] LOG:  invalid length of startup packet\n",
      "2025-03-29 14:45:04.504 -03 [18736] LOG:  invalid length of startup packet\n",
      "2025-03-29 14:45:04.525 -03 [19664] LOG:  invalid length of startup packet\n",
      "2025-03-29 14:45:04.545 -03 [304] LOG:  invalid length of startup packet\n",
      "2025-03-29 14:45:19.290 -03 [29996] LOG:  invalid length of startup packet\n",
      "2025-03-29 14:45:19.309 -03 [2752] LOG:  invalid length of startup packet\n",
      "2025-03-29 14:45:19.324 -03 [28712] LOG:  invalid length of startup packet\n",
      "2025-03-29 14:45:19.340 -03 [29784] LOG:  invalid length of startup packet\n",
      "2025-03-29 14:45:19.355 -03 [28180] LOG:  invalid length of startup packet\n",
      "2025-03-29 14:45:19.373 -03 [30272] LOG:  invalid length of startup packet\n",
      "2025-03-29 14:45:19.387 -03 [30164] LOG:  invalid length of startup packet\n",
      "2025-03-29 14:45:19.402 -03 [26244] LOG:  invalid length of startup packet\n",
      "2025-03-29 14:45:19.419 -03 [11676] LOG:  invalid length of startup packet\n",
      "2025-03-29 14:45:19.437 -03 [1452] LOG:  invalid length of startup packet\n",
      "2025-03-29 14:45:22.406 -03 [5636] LOG:  invalid length of startup packet\n",
      "2025-03-29 14:45:22.424 -03 [19960] LOG:  invalid length of startup packet\n",
      "2025-03-29 14:45:22.447 -03 [30016] LOG:  invalid length of startup packet\n",
      "2025-03-29 14:45:22.468 -03 [21868] LOG:  invalid length of startup packet\n",
      "2025-03-29 14:45:22.493 -03 [29760] LOG:  invalid length of startup packet\n",
      "2025-03-29 14:45:22.519 -03 [27052] LOG:  invalid length of startup packet\n",
      "2025-03-29 14:45:22.545 -03 [12868] LOG:  invalid length of startup packet\n",
      "2025-03-29 14:45:22.573 -03 [8504] LOG:  invalid length of startup packet\n",
      "2025-03-29 14:45:22.594 -03 [29952] LOG:  invalid length of startup packet\n",
      "2025-03-29 14:45:22.617 -03 [30044] LOG:  invalid length of startup packet\n",
      "2025-03-29 14:49:29.587 -03 [15964] LOG:  checkpoint starting: time\n",
      "2025-03-29 14:51:15.444 -03 [15964] LOG:  checkpoint complete: wrote 975 buffers (6.0%); 0 WAL file(s) added, 0 removed, 0 recycled; write=105.735 s, sync=0.110 s, total=105.858 s; sync files=334, longest=0.002 s, average=0.001 s; distance=4789 kB, estimate=4789 kB; lsn=0/192EF20, redo lsn=0/192EEE8\n",
      "2025-03-29 16:22:41.702 -03 [29376] LOG:  could not receive data from client: unrecognized winsock error 10054\n",
      "2025-03-29 16:22:51.273 -03 [16376] LOG:  server process (PID 26456) was terminated by exception 0xC0000142\n",
      "2025-03-29 16:22:51.273 -03 [16376] HINT:  See C include file \"ntstatus.h\" for a description of the hexadecimal value.\n",
      "2025-03-29 16:22:51.273 -03 [16376] LOG:  terminating any other active server processes\n",
      "2025-03-29 16:22:51.280 -03 [16376] LOG:  all server processes terminated; reinitializing\n",
      "2025-03-29 16:22:51.306 -03 [16376] LOG:  startup process (PID 22432) was terminated by exception 0xC0000142\n",
      "2025-03-29 16:22:51.306 -03 [16376] HINT:  See C include file \"ntstatus.h\" for a description of the hexadecimal value.\n",
      "2025-03-29 16:22:51.306 -03 [16376] LOG:  aborting startup due to startup process failure\n",
      "2025-03-29 16:22:51.308 -03 [16376] LOG:  database system is shut down\n",
      "2025-03-29 17:23:04.803 -03 [32744] LOG:  starting PostgreSQL 16.8 on x86_64-pc-mingw64, compiled by gcc.exe (x86_64-posix-seh-rev2, Built by MinGW-W64 project) 12.2.0, 64-bit\n",
      "2025-03-29 17:23:04.804 -03 [32744] LOG:  listening on IPv4 address \"127.0.0.1\", port 59749\n",
      "2025-03-29 17:23:04.857 -03 [31256] LOG:  database system was interrupted; last known up at 2025-03-29 14:51:15 -03\n",
      "2025-03-29 17:23:11.085 -03 [31256] LOG:  could not open file \"./log\": sharing violation\n",
      "2025-03-29 17:23:11.085 -03 [31256] DETAIL:  Continuing to retry for 30 seconds.\n",
      "2025-03-29 17:23:11.085 -03 [31256] HINT:  You might have antivirus, backup, or similar software interfering with the database system.\n",
      "2025-03-29 17:23:38.247 -03 [31256] LOG:  syncing data directory (fsync), elapsed time: 33.38 s, current path: ./pg_commit_ts\n",
      "2025-03-29 17:23:38.263 -03 [31256] LOG:  database system was not properly shut down; automatic recovery in progress\n",
      "2025-03-29 17:23:38.274 -03 [31256] LOG:  redo starts at 0/192EEE8\n",
      "2025-03-29 17:23:38.274 -03 [31256] LOG:  invalid record length at 0/192EFD0: expected at least 24, got 0\n",
      "2025-03-29 17:23:38.274 -03 [31256] LOG:  redo done at 0/192EF98 system usage: CPU: user: 0.00 s, system: 0.00 s, elapsed: 0.00 s\n",
      "2025-03-29 17:23:38.282 -03 [27864] LOG:  checkpoint starting: end-of-recovery immediate wait\n",
      "2025-03-29 17:23:38.291 -03 [27864] LOG:  checkpoint complete: wrote 3 buffers (0.0%); 0 WAL file(s) added, 0 removed, 0 recycled; write=0.003 s, sync=0.002 s, total=0.011 s; sync files=2, longest=0.001 s, average=0.001 s; distance=0 kB, estimate=0 kB; lsn=0/192EFD0, redo lsn=0/192EFD0\n",
      "2025-03-29 17:23:38.306 -03 [32744] LOG:  database system is ready to accept connections\n",
      "2025-03-29 17:23:38.307 -03 [32744] LOG:  WAL writer process (PID 18972) was terminated by exception 0xC0000142\n",
      "2025-03-29 17:23:38.307 -03 [32744] HINT:  See C include file \"ntstatus.h\" for a description of the hexadecimal value.\n",
      "2025-03-29 17:23:38.307 -03 [32744] LOG:  terminating any other active server processes\n",
      "2025-03-29 17:23:38.310 -03 [32744] LOG:  all server processes terminated; reinitializing\n",
      "2025-03-29 17:23:38.331 -03 [32744] LOG:  startup process (PID 13988) was terminated by exception 0xC0000142\n",
      "2025-03-29 17:23:38.331 -03 [32744] HINT:  See C include file \"ntstatus.h\" for a description of the hexadecimal value.\n",
      "2025-03-29 17:23:38.331 -03 [32744] LOG:  aborting startup due to startup process failure\n",
      "2025-03-29 17:23:38.332 -03 [32744] LOG:  database system is shut down\n",
      "2025-03-29 17:23:41.862 -03 [29196] LOG:  starting PostgreSQL 16.8 on x86_64-pc-mingw64, compiled by gcc.exe (x86_64-posix-seh-rev2, Built by MinGW-W64 project) 12.2.0, 64-bit\n",
      "2025-03-29 17:23:41.862 -03 [29196] LOG:  listening on IPv4 address \"127.0.0.1\", port 59835\n",
      "2025-03-29 17:23:41.895 -03 [32232] LOG:  database system was interrupted; last known up at 2025-03-29 17:23:38 -03\n",
      "2025-03-29 17:23:47.932 -03 [32232] LOG:  could not open file \"./log\": sharing violation\n",
      "2025-03-29 17:23:47.932 -03 [32232] DETAIL:  Continuing to retry for 30 seconds.\n",
      "2025-03-29 17:23:47.932 -03 [32232] HINT:  You might have antivirus, backup, or similar software interfering with the database system.\n",
      "2025-03-29 17:24:15.060 -03 [32232] LOG:  syncing data directory (fsync), elapsed time: 33.16 s, current path: ./pg_commit_ts\n",
      "2025-03-29 17:24:15.111 -03 [32232] LOG:  database system was not properly shut down; automatic recovery in progress\n",
      "2025-03-29 17:24:15.123 -03 [32232] LOG:  invalid record length at 0/192F048: expected at least 24, got 0\n",
      "2025-03-29 17:24:15.123 -03 [32232] LOG:  redo is not required\n",
      "2025-03-29 17:24:15.137 -03 [31464] LOG:  checkpoint starting: end-of-recovery immediate wait\n",
      "2025-03-29 17:24:15.154 -03 [31464] LOG:  checkpoint complete: wrote 3 buffers (0.0%); 0 WAL file(s) added, 0 removed, 0 recycled; write=0.006 s, sync=0.003 s, total=0.019 s; sync files=2, longest=0.002 s, average=0.002 s; distance=0 kB, estimate=0 kB; lsn=0/192F048, redo lsn=0/192F048\n",
      "2025-03-29 17:24:15.194 -03 [29196] LOG:  database system is ready to accept connections\n",
      "2025-03-29 17:24:15.205 -03 [29196] LOG:  background worker \"logical replication launcher\" (PID 31300) was terminated by exception 0xC0000142\n",
      "2025-03-29 17:24:15.205 -03 [29196] HINT:  See C include file \"ntstatus.h\" for a description of the hexadecimal value.\n",
      "2025-03-29 17:24:15.205 -03 [29196] LOG:  terminating any other active server processes\n",
      "2025-03-29 17:24:15.217 -03 [29196] LOG:  all server processes terminated; reinitializing\n",
      "2025-03-29 17:24:15.268 -03 [29196] LOG:  startup process (PID 17204) was terminated by exception 0xC0000142\n",
      "2025-03-29 17:24:15.268 -03 [29196] HINT:  See C include file \"ntstatus.h\" for a description of the hexadecimal value.\n",
      "2025-03-29 17:24:15.268 -03 [29196] LOG:  aborting startup due to startup process failure\n",
      "2025-03-29 17:24:15.270 -03 [29196] LOG:  database system is shut down\n",
      "2025-03-29 17:24:38.655 -03 [29852] LOG:  starting PostgreSQL 16.8 on x86_64-pc-mingw64, compiled by gcc.exe (x86_64-posix-seh-rev2, Built by MinGW-W64 project) 12.2.0, 64-bit\n",
      "2025-03-29 17:24:38.656 -03 [29852] LOG:  listening on IPv4 address \"127.0.0.1\", port 60049\n",
      "2025-03-29 17:24:38.692 -03 [27700] LOG:  database system was interrupted; last known up at 2025-03-29 17:24:15 -03\n",
      "2025-03-29 17:24:44.807 -03 [27700] LOG:  could not open file \"./log\": sharing violation\n",
      "2025-03-29 17:24:44.807 -03 [27700] DETAIL:  Continuing to retry for 30 seconds.\n",
      "2025-03-29 17:24:44.807 -03 [27700] HINT:  You might have antivirus, backup, or similar software interfering with the database system.\n",
      "2025-03-29 17:25:11.963 -03 [27700] LOG:  syncing data directory (fsync), elapsed time: 33.27 s, current path: ./pg_commit_ts\n",
      "2025-03-29 17:25:11.977 -03 [27700] LOG:  database system was not properly shut down; automatic recovery in progress\n",
      "2025-03-29 17:25:11.986 -03 [27700] LOG:  invalid record length at 0/192F0C0: expected at least 24, got 0\n",
      "2025-03-29 17:25:11.986 -03 [27700] LOG:  redo is not required\n",
      "2025-03-29 17:25:11.995 -03 [13996] LOG:  checkpoint starting: end-of-recovery immediate wait\n",
      "2025-03-29 17:25:12.004 -03 [13996] LOG:  checkpoint complete: wrote 3 buffers (0.0%); 0 WAL file(s) added, 0 removed, 0 recycled; write=0.002 s, sync=0.002 s, total=0.010 s; sync files=2, longest=0.001 s, average=0.001 s; distance=0 kB, estimate=0 kB; lsn=0/192F0C0, redo lsn=0/192F0C0\n",
      "2025-03-29 17:25:12.019 -03 [29852] LOG:  database system is ready to accept connections\n",
      "2025-03-29 17:25:42.088 -03 [31132] LOG:  could not receive data from client: unrecognized winsock error 10054\n",
      "2025-03-29 17:26:42.060 -03 [29852] LOG:  server process (PID 31556) was terminated by exception 0xC0000142\n",
      "2025-03-29 17:26:42.060 -03 [29852] HINT:  See C include file \"ntstatus.h\" for a description of the hexadecimal value.\n",
      "2025-03-29 17:26:42.060 -03 [29852] LOG:  terminating any other active server processes\n",
      "2025-03-29 17:26:42.063 -03 [29852] LOG:  all server processes terminated; reinitializing\n",
      "2025-03-29 17:26:42.084 -03 [29852] LOG:  startup process (PID 32616) was terminated by exception 0xC0000142\n",
      "2025-03-29 17:26:42.084 -03 [29852] HINT:  See C include file \"ntstatus.h\" for a description of the hexadecimal value.\n",
      "2025-03-29 17:26:42.084 -03 [29852] LOG:  aborting startup due to startup process failure\n",
      "2025-03-29 17:26:42.085 -03 [29852] LOG:  database system is shut down\n",
      "2025-03-29 17:26:42.434 -03 [31508] LOG:  starting PostgreSQL 16.8 on x86_64-pc-mingw64, compiled by gcc.exe (x86_64-posix-seh-rev2, Built by MinGW-W64 project) 12.2.0, 64-bit\n",
      "2025-03-29 17:26:42.435 -03 [31508] LOG:  listening on IPv4 address \"127.0.0.1\", port 60152\n",
      "2025-03-29 17:26:42.465 -03 [27804] LOG:  database system was interrupted; last known up at 2025-03-29 17:25:12 -03\n",
      "2025-03-29 17:26:48.507 -03 [27804] LOG:  could not open file \"./log\": sharing violation\n",
      "2025-03-29 17:26:48.507 -03 [27804] DETAIL:  Continuing to retry for 30 seconds.\n",
      "2025-03-29 17:26:48.507 -03 [27804] HINT:  You might have antivirus, backup, or similar software interfering with the database system.\n",
      "2025-03-29 17:27:15.646 -03 [27804] LOG:  syncing data directory (fsync), elapsed time: 33.18 s, current path: ./pg_commit_ts\n",
      "2025-03-29 17:27:15.656 -03 [27804] LOG:  database system was not properly shut down; automatic recovery in progress\n",
      "2025-03-29 17:27:15.662 -03 [27804] LOG:  redo starts at 0/192F138\n",
      "2025-03-29 17:27:15.663 -03 [27804] LOG:  invalid record length at 0/192F420: expected at least 24, got 0\n",
      "2025-03-29 17:27:15.663 -03 [27804] LOG:  redo done at 0/192F3E8 system usage: CPU: user: 0.00 s, system: 0.00 s, elapsed: 0.00 s\n",
      "2025-03-29 17:27:15.672 -03 [31472] LOG:  checkpoint starting: end-of-recovery immediate wait\n",
      "2025-03-29 17:27:15.682 -03 [31472] LOG:  checkpoint complete: wrote 5 buffers (0.0%); 0 WAL file(s) added, 0 removed, 0 recycled; write=0.003 s, sync=0.003 s, total=0.012 s; sync files=4, longest=0.001 s, average=0.001 s; distance=0 kB, estimate=0 kB; lsn=0/192F420, redo lsn=0/192F420\n",
      "2025-03-29 17:27:15.695 -03 [31508] LOG:  database system is ready to accept connections\n",
      "2025-03-29 17:27:45.798 -03 [31508] LOG:  server process (PID 17928) was terminated by exception 0xC0000142\n",
      "2025-03-29 17:27:45.798 -03 [31508] HINT:  See C include file \"ntstatus.h\" for a description of the hexadecimal value.\n",
      "2025-03-29 17:27:45.798 -03 [31508] LOG:  terminating any other active server processes\n",
      "2025-03-29 17:27:45.800 -03 [31508] LOG:  all server processes terminated; reinitializing\n",
      "2025-03-29 17:27:45.821 -03 [31508] LOG:  startup process (PID 28540) was terminated by exception 0xC0000142\n",
      "2025-03-29 17:27:45.821 -03 [31508] HINT:  See C include file \"ntstatus.h\" for a description of the hexadecimal value.\n",
      "2025-03-29 17:27:45.821 -03 [31508] LOG:  aborting startup due to startup process failure\n",
      "2025-03-29 17:27:45.822 -03 [31508] LOG:  database system is shut down\n",
      "2025-03-29 17:28:55.974 -03 [20416] LOG:  starting PostgreSQL 16.8 on x86_64-pc-mingw64, compiled by gcc.exe (x86_64-posix-seh-rev2, Built by MinGW-W64 project) 12.2.0, 64-bit\n",
      "2025-03-29 17:28:55.975 -03 [20416] LOG:  listening on IPv4 address \"127.0.0.1\", port 60370\n",
      "2025-03-29 17:28:56.020 -03 [27480] LOG:  database system was interrupted; last known up at 2025-03-29 17:27:15 -03\n",
      "2025-03-29 17:29:02.207 -03 [27480] LOG:  could not open file \"./log\": sharing violation\n",
      "2025-03-29 17:29:02.207 -03 [27480] DETAIL:  Continuing to retry for 30 seconds.\n",
      "2025-03-29 17:29:02.207 -03 [27480] HINT:  You might have antivirus, backup, or similar software interfering with the database system.\n",
      "2025-03-29 17:29:29.194 -03 [27480] LOG:  syncing data directory (fsync), elapsed time: 33.17 s, current path: ./pg_commit_ts\n",
      "2025-03-29 17:29:29.204 -03 [27480] LOG:  database system was not properly shut down; automatic recovery in progress\n",
      "2025-03-29 17:29:29.209 -03 [27480] LOG:  redo starts at 0/192F498\n",
      "2025-03-29 17:29:29.209 -03 [27480] LOG:  invalid record length at 0/192F4D0: expected at least 24, got 0\n",
      "2025-03-29 17:29:29.209 -03 [27480] LOG:  redo done at 0/192F498 system usage: CPU: user: 0.00 s, system: 0.00 s, elapsed: 0.00 s\n",
      "2025-03-29 17:29:29.218 -03 [32548] LOG:  checkpoint starting: end-of-recovery immediate wait\n",
      "2025-03-29 17:29:29.226 -03 [32548] LOG:  checkpoint complete: wrote 3 buffers (0.0%); 0 WAL file(s) added, 0 removed, 0 recycled; write=0.002 s, sync=0.002 s, total=0.009 s; sync files=2, longest=0.001 s, average=0.001 s; distance=0 kB, estimate=0 kB; lsn=0/192F4D0, redo lsn=0/192F4D0\n",
      "2025-03-29 17:29:29.239 -03 [20416] LOG:  database system is ready to accept connections\n",
      "2025-03-29 17:33:39.117 -03 [20416] LOG:  server process (PID 29092) was terminated by exception 0xC0000142\n",
      "2025-03-29 17:33:39.117 -03 [20416] HINT:  See C include file \"ntstatus.h\" for a description of the hexadecimal value.\n",
      "2025-03-29 17:33:39.117 -03 [20416] LOG:  terminating any other active server processes\n",
      "2025-03-29 17:33:39.120 -03 [20416] LOG:  all server processes terminated; reinitializing\n",
      "2025-03-29 17:33:39.140 -03 [20416] LOG:  startup process (PID 18576) was terminated by exception 0xC0000142\n",
      "2025-03-29 17:33:39.140 -03 [20416] HINT:  See C include file \"ntstatus.h\" for a description of the hexadecimal value.\n",
      "2025-03-29 17:33:39.140 -03 [20416] LOG:  aborting startup due to startup process failure\n",
      "2025-03-29 17:33:39.141 -03 [20416] LOG:  database system is shut down\n",
      "2025-03-29 17:34:03.248 -03 [24064] LOG:  starting PostgreSQL 16.8 on x86_64-pc-mingw64, compiled by gcc.exe (x86_64-posix-seh-rev2, Built by MinGW-W64 project) 12.2.0, 64-bit\n",
      "2025-03-29 17:34:03.249 -03 [24064] LOG:  listening on IPv4 address \"127.0.0.1\", port 60519\n",
      "2025-03-29 17:34:03.276 -03 [26472] LOG:  database system was interrupted; last known up at 2025-03-29 17:29:29 -03\n",
      "2025-03-29 17:34:09.340 -03 [26472] LOG:  could not open file \"./log\": sharing violation\n",
      "2025-03-29 17:34:09.340 -03 [26472] DETAIL:  Continuing to retry for 30 seconds.\n",
      "2025-03-29 17:34:09.340 -03 [26472] HINT:  You might have antivirus, backup, or similar software interfering with the database system.\n",
      "2025-03-29 17:34:36.440 -03 [26472] LOG:  syncing data directory (fsync), elapsed time: 33.16 s, current path: ./pg_commit_ts\n",
      "2025-03-29 17:34:36.453 -03 [26472] LOG:  database system was not properly shut down; automatic recovery in progress\n",
      "2025-03-29 17:34:36.459 -03 [26472] LOG:  redo starts at 0/192F548\n",
      "2025-03-29 17:34:36.459 -03 [26472] LOG:  invalid record length at 0/192F580: expected at least 24, got 0\n",
      "2025-03-29 17:34:36.459 -03 [26472] LOG:  redo done at 0/192F548 system usage: CPU: user: 0.00 s, system: 0.00 s, elapsed: 0.00 s\n",
      "2025-03-29 17:34:36.468 -03 [25780] LOG:  checkpoint starting: end-of-recovery immediate wait\n",
      "2025-03-29 17:34:36.476 -03 [25780] LOG:  checkpoint complete: wrote 3 buffers (0.0%); 0 WAL file(s) added, 0 removed, 0 recycled; write=0.003 s, sync=0.002 s, total=0.009 s; sync files=2, longest=0.001 s, average=0.001 s; distance=0 kB, estimate=0 kB; lsn=0/192F580, redo lsn=0/192F580\n",
      "2025-03-29 17:34:36.492 -03 [24064] LOG:  database system is ready to accept connections\n",
      "2025-03-29 17:34:43.448 -03 [22892] LOG:  could not receive data from client: unrecognized winsock error 10054\n",
      "2025-03-29 17:35:00.599 -03 [29916] LOG:  invalid length of startup packet\n",
      "2025-03-29 17:35:00.617 -03 [32672] LOG:  invalid length of startup packet\n",
      "2025-03-29 17:35:00.634 -03 [8624] LOG:  invalid length of startup packet\n",
      "2025-03-29 17:35:00.651 -03 [18476] LOG:  invalid length of startup packet\n",
      "2025-03-29 17:35:00.670 -03 [25232] LOG:  invalid length of startup packet\n",
      "2025-03-29 17:35:00.691 -03 [25856] LOG:  invalid length of startup packet\n",
      "2025-03-29 17:35:00.710 -03 [31496] LOG:  invalid length of startup packet\n",
      "2025-03-29 17:35:00.730 -03 [6700] LOG:  invalid length of startup packet\n",
      "2025-03-29 17:35:00.749 -03 [29092] LOG:  invalid length of startup packet\n",
      "2025-03-29 17:35:00.769 -03 [30184] LOG:  invalid length of startup packet\n",
      "2025-03-29 17:35:14.976 -03 [4696] LOG:  could not receive data from client: unrecognized winsock error 10054\n",
      "2025-03-29 17:35:24.188 -03 [31060] LOG:  could not receive data from client: unrecognized winsock error 10054\n",
      "2025-03-29 17:39:36.484 -03 [25780] LOG:  checkpoint starting: time\n",
      "2025-03-29 17:39:37.796 -03 [25780] LOG:  checkpoint complete: wrote 13 buffers (0.1%); 0 WAL file(s) added, 0 removed, 0 recycled; write=1.299 s, sync=0.005 s, total=1.312 s; sync files=8, longest=0.002 s, average=0.001 s; distance=2 kB, estimate=2 kB; lsn=0/1930120, redo lsn=0/19300E8\n",
      "2025-03-29 17:42:41.051 -03 [29280] LOG:  could not receive data from client: unrecognized winsock error 10054\n",
      "2025-03-29 17:44:36.797 -03 [25780] LOG:  checkpoint starting: time\n",
      "2025-03-29 17:44:44.553 -03 [25780] LOG:  checkpoint complete: wrote 72 buffers (0.4%); 0 WAL file(s) added, 0 removed, 0 recycled; write=7.723 s, sync=0.024 s, total=7.756 s; sync files=61, longest=0.001 s, average=0.001 s; distance=249 kB, estimate=249 kB; lsn=0/196E7F8, redo lsn=0/196E7C0\n",
      "2025-03-29 18:56:00.933 -03 [28976] LOG:  could not receive data from client: unrecognized winsock error 10054\n",
      "2025-03-29 18:56:01.338 -03 [19844] ERROR:  canceling statement due to user request\n",
      "2025-03-29 18:56:01.341 -03 [24064] LOG:  background worker \"logical replication launcher\" (PID 19844) was terminated by exception 0xC000013A\n",
      "2025-03-29 18:56:01.341 -03 [24064] HINT:  See C include file \"ntstatus.h\" for a description of the hexadecimal value.\n",
      "2025-03-29 18:56:01.341 -03 [24064] LOG:  terminating any other active server processes\n",
      "2025-03-29 18:56:01.350 -03 [24064] LOG:  all server processes terminated; reinitializing\n",
      "2025-03-29 18:56:01.391 -03 [24064] LOG:  startup process (PID 31260) was terminated by exception 0xC0000142\n",
      "2025-03-29 18:56:01.391 -03 [24064] HINT:  See C include file \"ntstatus.h\" for a description of the hexadecimal value.\n",
      "2025-03-29 18:56:01.391 -03 [24064] LOG:  aborting startup due to startup process failure\n",
      "2025-03-29 18:56:01.392 -03 [24064] LOG:  database system is shut down\n",
      "2025-04-07 19:09:05.499 -03 [17476] LOG:  starting PostgreSQL 16.8 on x86_64-pc-mingw64, compiled by gcc.exe (x86_64-posix-seh-rev2, Built by MinGW-W64 project) 12.2.0, 64-bit\n",
      "2025-04-07 19:09:05.500 -03 [17476] LOG:  listening on IPv4 address \"127.0.0.1\", port 51584\n",
      "2025-04-07 19:09:05.541 -03 [9276] LOG:  database system was interrupted; last known up at 2025-03-29 17:44:44 -03\n",
      "2025-04-07 19:09:11.768 -03 [9276] LOG:  could not open file \"./log\": sharing violation\n",
      "2025-04-07 19:09:11.768 -03 [9276] DETAIL:  Continuing to retry for 30 seconds.\n",
      "2025-04-07 19:09:11.768 -03 [9276] HINT:  You might have antivirus, backup, or similar software interfering with the database system.\n",
      "2025-04-07 19:09:38.942 -03 [9276] LOG:  syncing data directory (fsync), elapsed time: 33.40 s, current path: ./pg_commit_ts\n",
      "2025-04-07 19:09:38.964 -03 [9276] LOG:  database system was not properly shut down; automatic recovery in progress\n",
      "2025-04-07 19:09:38.973 -03 [9276] LOG:  redo starts at 0/196E7C0\n",
      "2025-04-07 19:09:38.973 -03 [9276] LOG:  invalid record length at 0/196E8A8: expected at least 24, got 0\n",
      "2025-04-07 19:09:38.973 -03 [9276] LOG:  redo done at 0/196E870 system usage: CPU: user: 0.00 s, system: 0.00 s, elapsed: 0.00 s\n",
      "2025-04-07 19:09:38.986 -03 [19912] LOG:  checkpoint starting: end-of-recovery immediate wait\n",
      "2025-04-07 19:09:39.000 -03 [19912] LOG:  checkpoint complete: wrote 3 buffers (0.0%); 0 WAL file(s) added, 0 removed, 0 recycled; write=0.004 s, sync=0.002 s, total=0.015 s; sync files=2, longest=0.002 s, average=0.001 s; distance=0 kB, estimate=0 kB; lsn=0/196E8A8, redo lsn=0/196E8A8\n",
      "2025-04-07 19:09:39.024 -03 [17476] LOG:  database system is ready to accept connections\n",
      "2025-04-07 19:14:38.000 -03 [19912] LOG:  checkpoint starting: time\n",
      "2025-04-07 19:14:45.124 -03 [19912] LOG:  checkpoint complete: wrote 66 buffers (0.4%); 0 WAL file(s) added, 0 removed, 0 recycled; write=7.098 s, sync=0.020 s, total=7.125 s; sync files=54, longest=0.001 s, average=0.001 s; distance=188 kB, estimate=188 kB; lsn=0/19C4450, redo lsn=0/199DAE0\n",
      "2025-04-07 19:16:27.840 -03 [9292] LOG:  could not receive data from client: unrecognized winsock error 10054\n",
      "2025-04-07 19:19:38.138 -03 [19912] LOG:  checkpoint starting: time\n",
      "2025-04-07 19:19:46.593 -03 [19912] LOG:  checkpoint complete: wrote 78 buffers (0.5%); 0 WAL file(s) added, 0 removed, 0 recycled; write=8.419 s, sync=0.025 s, total=8.455 s; sync files=49, longest=0.007 s, average=0.001 s; distance=255 kB, estimate=255 kB; lsn=0/19DD8E0, redo lsn=0/19DD8A8\n",
      "2025-04-07 19:22:45.964 -03 [17476] LOG:  server process (PID 23468) was terminated by exception 0xC000013A\n",
      "2025-04-07 19:22:45.964 -03 [17476] DETAIL:  Failed process was running: COMMIT\n",
      "2025-04-07 19:22:45.964 -03 [17476] HINT:  See C include file \"ntstatus.h\" for a description of the hexadecimal value.\n",
      "2025-04-07 19:22:45.964 -03 [17476] LOG:  terminating any other active server processes\n",
      "2025-04-07 19:22:45.970 -03 [17476] LOG:  all server processes terminated; reinitializing\n",
      "2025-04-07 19:22:46.007 -03 [23260] LOG:  database system was interrupted; last known up at 2025-04-07 19:19:46 -03\n",
      "2025-04-07 19:22:46.173 -03 [17476] LOG:  received fast shutdown request\n",
      "^C2025-04-07 19:22:52.335 -03 [23260] LOG:  could not open file \"./log\": sharing violation\n",
      "2025-04-07 19:22:52.335 -03 [23260] DETAIL:  Continuing to retry for 30 seconds.\n",
      "2025-04-07 19:22:52.335 -03 [23260] HINT:  You might have antivirus, backup, or similar software interfering with the database system.\n",
      "2025-04-07 19:23:19.525 -03 [23260] LOG:  syncing data directory (fsync), elapsed time: 33.51 s, current path: ./pg_commit_ts\n",
      "2025-04-07 19:23:19.544 -03 [23260] LOG:  database system was not properly shut down; automatic recovery in progress\n",
      "2025-04-07 19:23:19.551 -03 [23260] LOG:  redo starts at 0/19DD8A8\n",
      "2025-04-07 21:49:24.609 -03 [15684] LOG:  starting PostgreSQL 16.8 on x86_64-pc-mingw64, compiled by gcc.exe (x86_64-posix-seh-rev2, Built by MinGW-W64 project) 12.2.0, 64-bit\n",
      "2025-04-07 21:49:24.610 -03 [15684] LOG:  listening on IPv4 address \"127.0.0.1\", port 55571\n",
      "2025-04-07 21:49:24.697 -03 [15756] LOG:  database system was interrupted while in recovery at 2025-04-07 19:23:19 -03\n",
      "2025-04-07 21:49:24.697 -03 [15756] HINT:  This probably means that some data is corrupted and you will have to use the last backup for recovery.\n",
      "2025-04-07 21:49:32.029 -03 [15756] LOG:  could not open file \"./log\": sharing violation\n",
      "2025-04-07 21:49:32.029 -03 [15756] DETAIL:  Continuing to retry for 30 seconds.\n",
      "2025-04-07 21:49:32.029 -03 [15756] HINT:  You might have antivirus, backup, or similar software interfering with the database system.\n",
      "2025-04-07 21:49:59.173 -03 [15756] LOG:  syncing data directory (fsync), elapsed time: 34.47 s, current path: ./pg_commit_ts\n",
      "2025-04-07 21:49:59.211 -03 [15756] LOG:  database system was not properly shut down; automatic recovery in progress\n",
      "2025-04-07 21:49:59.232 -03 [15756] LOG:  redo starts at 0/19DD8A8\n",
      "2025-04-07 21:49:59.232 -03 [15756] LOG:  invalid record length at 0/19DD990: expected at least 24, got 0\n",
      "2025-04-07 21:49:59.232 -03 [15756] LOG:  redo done at 0/19DD958 system usage: CPU: user: 0.00 s, system: 0.00 s, elapsed: 0.00 s\n",
      "2025-04-07 21:49:59.252 -03 [12060] LOG:  checkpoint starting: end-of-recovery immediate wait\n",
      "2025-04-07 21:49:59.272 -03 [12060] LOG:  checkpoint complete: wrote 3 buffers (0.0%); 0 WAL file(s) added, 0 removed, 0 recycled; write=0.006 s, sync=0.003 s, total=0.023 s; sync files=2, longest=0.002 s, average=0.002 s; distance=0 kB, estimate=0 kB; lsn=0/19DD990, redo lsn=0/19DD990\n",
      "2025-04-07 21:49:59.299 -03 [15684] LOG:  database system is ready to accept connections\n",
      "2025-04-07 21:54:59.284 -03 [12060] LOG:  checkpoint starting: time\n",
      "2025-04-07 21:54:59.744 -03 [12060] LOG:  checkpoint complete: wrote 5 buffers (0.0%); 0 WAL file(s) added, 0 removed, 0 recycled; write=0.439 s, sync=0.005 s, total=0.460 s; sync files=4, longest=0.002 s, average=0.002 s; distance=12 kB, estimate=12 kB; lsn=0/19E0A58, redo lsn=0/19E0A20\n",
      "2025-04-07 22:06:52.737 -03 [1216] LOG:  could not receive data from client: unrecognized winsock error 10054\n",
      "2025-04-07 22:09:59.762 -03 [12060] LOG:  checkpoint starting: time\n",
      "2025-04-07 22:10:00.007 -03 [12060] LOG:  checkpoint complete: wrote 3 buffers (0.0%); 0 WAL file(s) added, 0 removed, 0 recycled; write=0.219 s, sync=0.010 s, total=0.246 s; sync files=3, longest=0.008 s, average=0.004 s; distance=4 kB, estimate=11 kB; lsn=0/19E1E28, redo lsn=0/19E1DF0\n",
      "2025-04-07 22:16:46.714 -03 [19992] LOG:  could not receive data from client: unrecognized winsock error 10054\n",
      "2025-04-07 22:18:46.884 -03 [14584] LOG:  could not receive data from client: unrecognized winsock error 10054\n",
      "2025-04-07 22:19:59.034 -03 [12060] LOG:  checkpoint starting: time\n",
      "2025-04-07 22:19:59.295 -03 [12060] LOG:  checkpoint complete: wrote 3 buffers (0.0%); 0 WAL file(s) added, 0 removed, 0 recycled; write=0.226 s, sync=0.011 s, total=0.261 s; sync files=3, longest=0.008 s, average=0.004 s; distance=5 kB, estimate=10 kB; lsn=0/19E3480, redo lsn=0/19E3448\n",
      "2025-04-07 22:30:55.793 -03 [22000] LOG:  could not receive data from client: unrecognized winsock error 10054\n",
      "2025-04-07 22:34:59.325 -03 [12060] LOG:  checkpoint starting: time\n",
      "2025-04-07 22:34:59.592 -03 [12060] LOG:  checkpoint complete: wrote 3 buffers (0.0%); 0 WAL file(s) added, 0 removed, 0 recycled; write=0.227 s, sync=0.013 s, total=0.267 s; sync files=3, longest=0.009 s, average=0.005 s; distance=5 kB, estimate=10 kB; lsn=0/19E4938, redo lsn=0/19E4900\n",
      "2025-04-07 22:39:29.907 -03 [21204] LOG:  could not receive data from client: unrecognized winsock error 10054\n",
      "2025-04-07 22:39:30.615 -03 [15684] LOG:  received fast shutdown request\n",
      "2025-04-08 20:27:46.924 -03 [33316] LOG:  starting PostgreSQL 16.8 on x86_64-pc-mingw64, compiled by gcc.exe (x86_64-posix-seh-rev2, Built by MinGW-W64 project) 12.2.0, 64-bit\n",
      "2025-04-08 20:27:46.925 -03 [33316] LOG:  listening on IPv4 address \"127.0.0.1\", port 52390\n",
      "2025-04-08 20:27:46.969 -03 [31928] LOG:  database system was interrupted; last known up at 2025-04-07 22:34:59 -03\n",
      "2025-04-08 20:27:53.242 -03 [31928] LOG:  could not open file \"./log\": sharing violation\n",
      "2025-04-08 20:27:53.242 -03 [31928] DETAIL:  Continuing to retry for 30 seconds.\n",
      "2025-04-08 20:27:53.242 -03 [31928] HINT:  You might have antivirus, backup, or similar software interfering with the database system.\n",
      "2025-04-08 20:28:20.364 -03 [31928] LOG:  syncing data directory (fsync), elapsed time: 33.39 s, current path: ./pg_commit_ts\n",
      "2025-04-08 20:28:20.382 -03 [31928] LOG:  database system was not properly shut down; automatic recovery in progress\n",
      "2025-04-08 20:28:20.390 -03 [31928] LOG:  redo starts at 0/19E4900\n",
      "2025-04-08 20:28:20.390 -03 [31928] LOG:  invalid record length at 0/19E49E8: expected at least 24, got 0\n",
      "2025-04-08 20:28:20.390 -03 [31928] LOG:  redo done at 0/19E49B0 system usage: CPU: user: 0.00 s, system: 0.00 s, elapsed: 0.00 s\n",
      "2025-04-08 20:28:20.402 -03 [25972] LOG:  checkpoint starting: end-of-recovery immediate wait\n",
      "2025-04-08 20:28:20.411 -03 [25972] LOG:  checkpoint complete: wrote 3 buffers (0.0%); 0 WAL file(s) added, 0 removed, 0 recycled; write=0.003 s, sync=0.002 s, total=0.011 s; sync files=2, longest=0.001 s, average=0.001 s; distance=0 kB, estimate=0 kB; lsn=0/19E49E8, redo lsn=0/19E49E8\n",
      "2025-04-08 20:28:20.425 -03 [33316] LOG:  database system is ready to accept connections\n",
      "2025-04-08 20:31:39.347 -03 [27072] LOG:  could not receive data from client: unrecognized winsock error 10054\n",
      "2025-04-08 20:33:20.420 -03 [25972] LOG:  checkpoint starting: time\n",
      "2025-04-08 20:33:20.667 -03 [25972] LOG:  checkpoint complete: wrote 3 buffers (0.0%); 0 WAL file(s) added, 0 removed, 0 recycled; write=0.225 s, sync=0.010 s, total=0.248 s; sync files=3, longest=0.007 s, average=0.004 s; distance=5 kB, estimate=5 kB; lsn=0/19E5F90, redo lsn=0/19E5F58\n",
      "2025-04-08 20:34:42.995 -03 [3080] LOG:  could not receive data from client: unrecognized winsock error 10054\n",
      "2025-04-08 20:35:23.678 -03 [33316] LOG:  received fast shutdown request\n",
      "2025-04-08 20:35:23.678 -03 [14436] ERROR:  canceling statement due to user request\n",
      "2025-04-08 20:35:23.679 -03 [33316] LOG:  aborting any active transactions\n",
      "2025-04-08 20:35:23.680 -03 [32644] FATAL:  terminating connection due to administrator command\n",
      "2025-04-08 20:35:23.681 -03 [33316] LOG:  background worker \"logical replication launcher\" (PID 14436) exited with exit code 1\n",
      "2025-04-08 20:35:23.683 -03 [25972] LOG:  shutting down\n",
      "2025-04-08 20:35:23.685 -03 [25972] LOG:  checkpoint starting: shutdown immediate\n",
      "2025-04-08 20:35:23.692 -03 [25972] LOG:  checkpoint complete: wrote 3 buffers (0.0%); 0 WAL file(s) added, 0 removed, 0 recycled; write=0.002 s, sync=0.002 s, total=0.009 s; sync files=3, longest=0.001 s, average=0.001 s; distance=4 kB, estimate=5 kB; lsn=0/19E7340, redo lsn=0/19E7340\n",
      "2025-04-08 20:35:23.698 -03 [33316] LOG:  database system is shut down\n",
      "2025-04-08 20:48:49.039 -03 [20872] LOG:  starting PostgreSQL 16.8 on x86_64-pc-mingw64, compiled by gcc.exe (x86_64-posix-seh-rev2, Built by MinGW-W64 project) 12.2.0, 64-bit\n",
      "2025-04-08 20:48:49.040 -03 [20872] LOG:  listening on IPv4 address \"127.0.0.1\", port 53140\n",
      "2025-04-08 20:48:49.079 -03 [11332] LOG:  database system was shut down at 2025-04-08 20:35:23 -03\n",
      "2025-04-08 20:48:49.100 -03 [20872] LOG:  database system is ready to accept connections\n",
      "2025-04-08 20:49:28.262 -03 [25648] LOG:  could not receive data from client: unrecognized winsock error 10054\n",
      "2025-04-08 20:49:47.030 -03 [20872] LOG:  server process (PID 8076) was terminated by exception 0xC0000142\n",
      "2025-04-08 20:49:47.030 -03 [20872] HINT:  See C include file \"ntstatus.h\" for a description of the hexadecimal value.\n",
      "2025-04-08 20:49:47.030 -03 [20872] LOG:  terminating any other active server processes\n",
      "2025-04-08 20:49:47.033 -03 [20872] LOG:  all server processes terminated; reinitializing\n",
      "2025-04-08 20:49:47.061 -03 [20872] LOG:  startup process (PID 26964) was terminated by exception 0xC0000142\n",
      "2025-04-08 20:49:47.061 -03 [20872] HINT:  See C include file \"ntstatus.h\" for a description of the hexadecimal value.\n",
      "2025-04-08 20:49:47.061 -03 [20872] LOG:  aborting startup due to startup process failure\n",
      "2025-04-08 20:49:47.062 -03 [20872] LOG:  database system is shut down\n",
      "2025-04-08 20:50:12.416 -03 [24108] LOG:  starting PostgreSQL 16.8 on x86_64-pc-mingw64, compiled by gcc.exe (x86_64-posix-seh-rev2, Built by MinGW-W64 project) 12.2.0, 64-bit\n",
      "2025-04-08 20:50:12.417 -03 [24108] LOG:  listening on IPv4 address \"127.0.0.1\", port 53312\n",
      "2025-04-08 20:50:12.451 -03 [27520] LOG:  database system was interrupted; last known up at 2025-04-08 20:48:49 -03\n",
      "2025-04-08 20:50:18.723 -03 [27520] LOG:  could not open file \"./log\": sharing violation\n",
      "2025-04-08 20:50:18.723 -03 [27520] DETAIL:  Continuing to retry for 30 seconds.\n",
      "2025-04-08 20:50:18.723 -03 [27520] HINT:  You might have antivirus, backup, or similar software interfering with the database system.\n",
      "2025-04-08 20:50:45.841 -03 [27520] LOG:  syncing data directory (fsync), elapsed time: 33.39 s, current path: ./pg_commit_ts\n",
      "2025-04-08 20:50:45.854 -03 [27520] LOG:  database system was not properly shut down; automatic recovery in progress\n",
      "2025-04-08 20:50:45.862 -03 [27520] LOG:  redo starts at 0/19E73B8\n",
      "2025-04-08 20:50:45.864 -03 [27520] LOG:  invalid record length at 0/19E8750: expected at least 24, got 0\n",
      "2025-04-08 20:50:45.864 -03 [27520] LOG:  redo done at 0/19E8718 system usage: CPU: user: 0.00 s, system: 0.00 s, elapsed: 0.00 s\n",
      "2025-04-08 20:50:45.874 -03 [33428] LOG:  checkpoint starting: end-of-recovery immediate wait\n",
      "2025-04-08 20:50:45.886 -03 [33428] LOG:  checkpoint complete: wrote 5 buffers (0.0%); 0 WAL file(s) added, 0 removed, 0 recycled; write=0.003 s, sync=0.004 s, total=0.013 s; sync files=4, longest=0.001 s, average=0.001 s; distance=5 kB, estimate=5 kB; lsn=0/19E8750, redo lsn=0/19E8750\n",
      "2025-04-08 20:50:45.900 -03 [24108] LOG:  database system is ready to accept connections\n",
      "2025-04-08 20:51:40.759 -03 [24108] LOG:  server process (PID 33272) was terminated by exception 0xC0000142\n",
      "2025-04-08 20:51:40.759 -03 [24108] HINT:  See C include file \"ntstatus.h\" for a description of the hexadecimal value.\n",
      "2025-04-08 20:51:40.759 -03 [24108] LOG:  terminating any other active server processes\n",
      "2025-04-08 20:51:40.825 -03 [24108] LOG:  all server processes terminated; reinitializing\n",
      "2025-04-08 20:51:40.849 -03 [24108] LOG:  startup process (PID 27800) was terminated by exception 0xC0000142\n",
      "2025-04-08 20:51:40.849 -03 [24108] HINT:  See C include file \"ntstatus.h\" for a description of the hexadecimal value.\n",
      "2025-04-08 20:51:40.849 -03 [24108] LOG:  aborting startup due to startup process failure\n",
      "2025-04-08 20:51:40.850 -03 [24108] LOG:  database system is shut down\n",
      "2025-04-08 20:52:02.354 -03 [12676] LOG:  starting PostgreSQL 16.8 on x86_64-pc-mingw64, compiled by gcc.exe (x86_64-posix-seh-rev2, Built by MinGW-W64 project) 12.2.0, 64-bit\n",
      "2025-04-08 20:52:02.355 -03 [12676] LOG:  listening on IPv4 address \"127.0.0.1\", port 53481\n",
      "2025-04-08 20:52:02.392 -03 [27572] LOG:  database system was interrupted; last known up at 2025-04-08 20:50:45 -03\n",
      "2025-04-08 20:52:08.550 -03 [27572] LOG:  could not open file \"./log\": sharing violation\n",
      "2025-04-08 20:52:08.550 -03 [27572] DETAIL:  Continuing to retry for 30 seconds.\n",
      "2025-04-08 20:52:08.550 -03 [27572] HINT:  You might have antivirus, backup, or similar software interfering with the database system.\n",
      "\n"
     ]
    },
    {
     "ename": "TimeoutExpired",
     "evalue": "Command '['c:\\\\Dev\\\\PPS\\\\env\\\\Lib\\\\site-packages\\\\pixeltable_pgserver\\\\pginstall\\\\bin\\\\pg_ctl.exe', '-D', 'C:\\\\Users\\\\mateo\\\\.pixeltable\\\\pgdata', '-w', '-o', '-h \"127.0.0.1\"', '-o', '-p 53481', '-l', 'C:\\\\Users\\\\mateo\\\\.pixeltable\\\\pgdata\\\\log', 'start']' timed out after 10.0 seconds",
     "output_type": "error",
     "traceback": [
      "\u001b[31m---------------------------------------------------------------------------\u001b[39m",
      "\u001b[31mTimeoutExpired\u001b[39m                            Traceback (most recent call last)",
      "\u001b[36mCell\u001b[39m\u001b[36m \u001b[39m\u001b[32mIn[3]\u001b[39m\u001b[32m, line 2\u001b[39m\n\u001b[32m      1\u001b[39m \u001b[38;5;66;03m# Inicializa el procesador de imágenes\u001b[39;00m\n\u001b[32m----> \u001b[39m\u001b[32m2\u001b[39m image_processor = \u001b[43mImageProcessor\u001b[49m\u001b[43m(\u001b[49m\u001b[43m)\u001b[49m\n\u001b[32m      3\u001b[39m image_processor.setup_processing(extract_text=\u001b[38;5;28;01mTrue\u001b[39;00m, enable_search=\u001b[38;5;28;01mTrue\u001b[39;00m)\n\u001b[32m      5\u001b[39m \u001b[38;5;28mprint\u001b[39m(\u001b[33m\"\u001b[39m\u001b[33mSetup terminado\u001b[39m\u001b[33m\"\u001b[39m)\n",
      "\u001b[36mFile \u001b[39m\u001b[32mc:\\Dev\\PPS\\Pixeltable\\image_video_processor.py:15\u001b[39m, in \u001b[36mImageProcessor.__init__\u001b[39m\u001b[34m(self, model, confidence_threshold)\u001b[39m\n\u001b[32m     13\u001b[39m \u001b[38;5;28mself\u001b[39m.model = model\n\u001b[32m     14\u001b[39m \u001b[38;5;28mself\u001b[39m.confidence_threshold = confidence_threshold\n\u001b[32m---> \u001b[39m\u001b[32m15\u001b[39m \u001b[38;5;28mself\u001b[39m.table = \u001b[43mpxt\u001b[49m\u001b[43m.\u001b[49m\u001b[43mcreate_table\u001b[49m\u001b[43m(\u001b[49m\u001b[33;43m'\u001b[39;49m\u001b[33;43mimages\u001b[39;49m\u001b[33;43m'\u001b[39;49m\u001b[43m,\u001b[49m\u001b[43m \u001b[49m\u001b[43m{\u001b[49m\u001b[33;43m'\u001b[39;49m\u001b[33;43mimage\u001b[39;49m\u001b[33;43m'\u001b[39;49m\u001b[43m:\u001b[49m\u001b[43m \u001b[49m\u001b[43mpxt\u001b[49m\u001b[43m.\u001b[49m\u001b[43mImageType\u001b[49m\u001b[43m(\u001b[49m\u001b[43m)\u001b[49m\u001b[43m}\u001b[49m\u001b[43m,\u001b[49m\u001b[43m \u001b[49m\u001b[43mif_exists\u001b[49m\u001b[43m=\u001b[49m\u001b[33;43m'\u001b[39;49m\u001b[33;43mignore\u001b[39;49m\u001b[33;43m'\u001b[39;49m\u001b[43m)\u001b[49m\n",
      "\u001b[36mFile \u001b[39m\u001b[32mc:\\Dev\\PPS\\env\\Lib\\site-packages\\pixeltable\\globals.py:113\u001b[39m, in \u001b[36mcreate_table\u001b[39m\u001b[34m(path, schema_or_df, primary_key, num_retained_versions, comment, media_validation, if_exists)\u001b[39m\n\u001b[32m    110\u001b[39m     \u001b[38;5;28;01mraise\u001b[39;00m excs.Error(\u001b[33m'\u001b[39m\u001b[33mprimary_key must be a single column name or a list of column names\u001b[39m\u001b[33m'\u001b[39m)\n\u001b[32m    112\u001b[39m media_validation_ = catalog.MediaValidation.validated(media_validation, \u001b[33m'\u001b[39m\u001b[33mmedia_validation\u001b[39m\u001b[33m'\u001b[39m)\n\u001b[32m--> \u001b[39m\u001b[32m113\u001b[39m \u001b[38;5;28;01mreturn\u001b[39;00m \u001b[43mCatalog\u001b[49m\u001b[43m.\u001b[49m\u001b[43mget\u001b[49m\u001b[43m(\u001b[49m\u001b[43m)\u001b[49m.create_table(\n\u001b[32m    114\u001b[39m     path_obj,\n\u001b[32m    115\u001b[39m     schema,\n\u001b[32m    116\u001b[39m     df,\n\u001b[32m    117\u001b[39m     if_exists=if_exists_,\n\u001b[32m    118\u001b[39m     primary_key=primary_key,\n\u001b[32m    119\u001b[39m     comment=comment,\n\u001b[32m    120\u001b[39m     media_validation=media_validation_,\n\u001b[32m    121\u001b[39m     num_retained_versions=num_retained_versions,\n\u001b[32m    122\u001b[39m )\n",
      "\u001b[36mFile \u001b[39m\u001b[32mc:\\Dev\\PPS\\env\\Lib\\site-packages\\pixeltable\\catalog\\catalog.py:113\u001b[39m, in \u001b[36mCatalog.get\u001b[39m\u001b[34m(cls)\u001b[39m\n\u001b[32m    110\u001b[39m \u001b[38;5;129m@classmethod\u001b[39m\n\u001b[32m    111\u001b[39m \u001b[38;5;28;01mdef\u001b[39;00m\u001b[38;5;250m \u001b[39m\u001b[34mget\u001b[39m(\u001b[38;5;28mcls\u001b[39m) -> Catalog:\n\u001b[32m    112\u001b[39m     \u001b[38;5;28;01mif\u001b[39;00m \u001b[38;5;28mcls\u001b[39m._instance \u001b[38;5;129;01mis\u001b[39;00m \u001b[38;5;28;01mNone\u001b[39;00m:\n\u001b[32m--> \u001b[39m\u001b[32m113\u001b[39m         \u001b[38;5;28mcls\u001b[39m._instance = \u001b[38;5;28;43mcls\u001b[39;49m\u001b[43m(\u001b[49m\u001b[43m)\u001b[49m\n\u001b[32m    114\u001b[39m     \u001b[38;5;28;01mreturn\u001b[39;00m \u001b[38;5;28mcls\u001b[39m._instance\n",
      "\u001b[36mFile \u001b[39m\u001b[32mc:\\Dev\\PPS\\env\\Lib\\site-packages\\pixeltable\\catalog\\catalog.py:124\u001b[39m, in \u001b[36mCatalog.__init__\u001b[39m\u001b[34m(self)\u001b[39m\n\u001b[32m    122\u001b[39m \u001b[38;5;28mself\u001b[39m._tbl_versions = {}\n\u001b[32m    123\u001b[39m \u001b[38;5;28mself\u001b[39m._tbls = {}  \u001b[38;5;66;03m# don't use a defaultdict here, it doesn't cooperate with the debugger\u001b[39;00m\n\u001b[32m--> \u001b[39m\u001b[32m124\u001b[39m \u001b[38;5;28;43mself\u001b[39;49m\u001b[43m.\u001b[49m\u001b[43m_init_store\u001b[49m\u001b[43m(\u001b[49m\u001b[43m)\u001b[49m\n",
      "\u001b[36mFile \u001b[39m\u001b[32mc:\\Dev\\PPS\\env\\Lib\\site-packages\\pixeltable\\catalog\\catalog.py:761\u001b[39m, in \u001b[36mCatalog._init_store\u001b[39m\u001b[34m(self)\u001b[39m\n\u001b[32m    759\u001b[39m \u001b[38;5;28;01mdef\u001b[39;00m\u001b[38;5;250m \u001b[39m\u001b[34m_init_store\u001b[39m(\u001b[38;5;28mself\u001b[39m) -> \u001b[38;5;28;01mNone\u001b[39;00m:\n\u001b[32m    760\u001b[39m \u001b[38;5;250m    \u001b[39m\u001b[33;03m\"\"\"One-time initialization of the stored catalog. Idempotent.\"\"\"\u001b[39;00m\n\u001b[32m--> \u001b[39m\u001b[32m761\u001b[39m     \u001b[38;5;28;01mwith\u001b[39;00m \u001b[43mEnv\u001b[49m\u001b[43m.\u001b[49m\u001b[43mget\u001b[49m\u001b[43m(\u001b[49m\u001b[43m)\u001b[49m.begin_xact():\n\u001b[32m    762\u001b[39m         session = Env.get().session\n\u001b[32m    763\u001b[39m         \u001b[38;5;28;01mif\u001b[39;00m session.query(sql.func.count(schema.Dir.id)).scalar() > \u001b[32m0\u001b[39m:\n",
      "\u001b[36mFile \u001b[39m\u001b[32mc:\\Dev\\PPS\\env\\Lib\\site-packages\\pixeltable\\env.py:88\u001b[39m, in \u001b[36mEnv.get\u001b[39m\u001b[34m(cls)\u001b[39m\n\u001b[32m     85\u001b[39m \u001b[38;5;129m@classmethod\u001b[39m\n\u001b[32m     86\u001b[39m \u001b[38;5;28;01mdef\u001b[39;00m\u001b[38;5;250m \u001b[39m\u001b[34mget\u001b[39m(\u001b[38;5;28mcls\u001b[39m) -> Env:\n\u001b[32m     87\u001b[39m     \u001b[38;5;28;01mif\u001b[39;00m \u001b[38;5;28mcls\u001b[39m._instance \u001b[38;5;129;01mis\u001b[39;00m \u001b[38;5;28;01mNone\u001b[39;00m:\n\u001b[32m---> \u001b[39m\u001b[32m88\u001b[39m         \u001b[38;5;28;43mcls\u001b[39;49m\u001b[43m.\u001b[49m\u001b[43m_init_env\u001b[49m\u001b[43m(\u001b[49m\u001b[43m)\u001b[49m\n\u001b[32m     89\u001b[39m     \u001b[38;5;28;01mreturn\u001b[39;00m \u001b[38;5;28mcls\u001b[39m._instance\n",
      "\u001b[36mFile \u001b[39m\u001b[32mc:\\Dev\\PPS\\env\\Lib\\site-packages\\pixeltable\\env.py:96\u001b[39m, in \u001b[36mEnv._init_env\u001b[39m\u001b[34m(cls, reinit_db)\u001b[39m\n\u001b[32m     94\u001b[39m \u001b[38;5;28mcls\u001b[39m.__initializing = \u001b[38;5;28;01mTrue\u001b[39;00m\n\u001b[32m     95\u001b[39m env = Env()\n\u001b[32m---> \u001b[39m\u001b[32m96\u001b[39m \u001b[43menv\u001b[49m\u001b[43m.\u001b[49m\u001b[43m_set_up\u001b[49m\u001b[43m(\u001b[49m\u001b[43mreinit_db\u001b[49m\u001b[43m=\u001b[49m\u001b[43mreinit_db\u001b[49m\u001b[43m)\u001b[49m\n\u001b[32m     97\u001b[39m env._upgrade_metadata()\n\u001b[32m     98\u001b[39m \u001b[38;5;28mcls\u001b[39m._instance = env\n",
      "\u001b[36mFile \u001b[39m\u001b[32mc:\\Dev\\PPS\\env\\Lib\\site-packages\\pixeltable\\env.py:357\u001b[39m, in \u001b[36mEnv._set_up\u001b[39m\u001b[34m(self, echo, reinit_db)\u001b[39m\n\u001b[32m    352\u001b[39m \u001b[38;5;66;03m# cleanup_mode=None will leave the postgres process running after Python exits\u001b[39;00m\n\u001b[32m    353\u001b[39m \u001b[38;5;66;03m# cleanup_mode='stop' will terminate the postgres process when Python exits\u001b[39;00m\n\u001b[32m    354\u001b[39m \u001b[38;5;66;03m# On Windows, we need cleanup_mode='stop' because child processes are killed automatically when the parent\u001b[39;00m\n\u001b[32m    355\u001b[39m \u001b[38;5;66;03m# process (such as Terminal or VSCode) exits, potentially leaving it in an unusable state.\u001b[39;00m\n\u001b[32m    356\u001b[39m cleanup_mode = \u001b[33m'\u001b[39m\u001b[33mstop\u001b[39m\u001b[33m'\u001b[39m \u001b[38;5;28;01mif\u001b[39;00m platform.system() == \u001b[33m'\u001b[39m\u001b[33mWindows\u001b[39m\u001b[33m'\u001b[39m \u001b[38;5;28;01melse\u001b[39;00m \u001b[38;5;28;01mNone\u001b[39;00m\n\u001b[32m--> \u001b[39m\u001b[32m357\u001b[39m \u001b[38;5;28mself\u001b[39m._db_server = \u001b[43mpixeltable_pgserver\u001b[49m\u001b[43m.\u001b[49m\u001b[43mget_server\u001b[49m\u001b[43m(\u001b[49m\u001b[38;5;28;43mself\u001b[39;49m\u001b[43m.\u001b[49m\u001b[43m_pgdata_dir\u001b[49m\u001b[43m,\u001b[49m\u001b[43m \u001b[49m\u001b[43mcleanup_mode\u001b[49m\u001b[43m=\u001b[49m\u001b[43mcleanup_mode\u001b[49m\u001b[43m)\u001b[49m\n\u001b[32m    358\u001b[39m \u001b[38;5;28mself\u001b[39m._db_url = \u001b[38;5;28mself\u001b[39m._db_server.get_uri(database=\u001b[38;5;28mself\u001b[39m._db_name, driver=\u001b[33m'\u001b[39m\u001b[33mpsycopg\u001b[39m\u001b[33m'\u001b[39m)\n\u001b[32m    360\u001b[39m tz_name = config.get_string_value(\u001b[33m'\u001b[39m\u001b[33mtime_zone\u001b[39m\u001b[33m'\u001b[39m)\n",
      "\u001b[36mFile \u001b[39m\u001b[32mc:\\Dev\\PPS\\env\\Lib\\site-packages\\pixeltable_pgserver\\postgres_server.py:306\u001b[39m, in \u001b[36mget_server\u001b[39m\u001b[34m(pgdata, cleanup_mode)\u001b[39m\n\u001b[32m    303\u001b[39m \u001b[38;5;28;01mif\u001b[39;00m pgdata \u001b[38;5;129;01min\u001b[39;00m PostgresServer._instances:\n\u001b[32m    304\u001b[39m     \u001b[38;5;28;01mreturn\u001b[39;00m PostgresServer._instances[pgdata]\n\u001b[32m--> \u001b[39m\u001b[32m306\u001b[39m \u001b[38;5;28;01mreturn\u001b[39;00m \u001b[43mPostgresServer\u001b[49m\u001b[43m(\u001b[49m\u001b[43mpgdata\u001b[49m\u001b[43m,\u001b[49m\u001b[43m \u001b[49m\u001b[43mcleanup_mode\u001b[49m\u001b[43m=\u001b[49m\u001b[43mcleanup_mode\u001b[49m\u001b[43m)\u001b[49m\n",
      "\u001b[36mFile \u001b[39m\u001b[32mc:\\Dev\\PPS\\env\\Lib\\site-packages\\pixeltable_pgserver\\postgres_server.py:69\u001b[39m, in \u001b[36mPostgresServer.__init__\u001b[39m\u001b[34m(self, pgdata, cleanup_mode)\u001b[39m\n\u001b[32m     67\u001b[39m \u001b[38;5;28mself\u001b[39m._instances[\u001b[38;5;28mself\u001b[39m.pgdata] = \u001b[38;5;28mself\u001b[39m\n\u001b[32m     68\u001b[39m \u001b[38;5;28mself\u001b[39m.ensure_pgdata_inited()\n\u001b[32m---> \u001b[39m\u001b[32m69\u001b[39m \u001b[38;5;28;43mself\u001b[39;49m\u001b[43m.\u001b[49m\u001b[43mensure_postgres_running\u001b[49m\u001b[43m(\u001b[49m\u001b[43m)\u001b[49m\n\u001b[32m     70\u001b[39m \u001b[38;5;28mself\u001b[39m.global_process_id_list.get_and_add(os.getpid())\n",
      "\u001b[36mFile \u001b[39m\u001b[32mc:\\Dev\\PPS\\env\\Lib\\site-packages\\pixeltable_pgserver\\postgres_server.py:199\u001b[39m, in \u001b[36mPostgresServer.ensure_postgres_running\u001b[39m\u001b[34m(self)\u001b[39m\n\u001b[32m    195\u001b[39m \u001b[38;5;28;01mexcept\u001b[39;00m subprocess.TimeoutExpired \u001b[38;5;28;01mas\u001b[39;00m err:\n\u001b[32m    196\u001b[39m     _logger.error(\n\u001b[32m    197\u001b[39m         \u001b[33mf\u001b[39m\u001b[33m'\u001b[39m\u001b[33mTimeout starting server.\u001b[39m\u001b[38;5;130;01m\\n\u001b[39;00m\u001b[33mShowing contents of postgres server log (\u001b[39m\u001b[38;5;132;01m{\u001b[39;00m\u001b[38;5;28mself\u001b[39m.log.absolute()\u001b[38;5;132;01m}\u001b[39;00m\u001b[33m) below:\u001b[39m\u001b[38;5;130;01m\\n\u001b[39;00m\u001b[38;5;132;01m{\u001b[39;00m\u001b[38;5;28mself\u001b[39m.log.read_text()\u001b[38;5;132;01m}\u001b[39;00m\u001b[33m'\u001b[39m\n\u001b[32m    198\u001b[39m     )\n\u001b[32m--> \u001b[39m\u001b[32m199\u001b[39m     \u001b[38;5;28;01mraise\u001b[39;00m err\n\u001b[32m    201\u001b[39m \u001b[38;5;28;01mwhile\u001b[39;00m \u001b[38;5;28;01mTrue\u001b[39;00m:\n\u001b[32m    202\u001b[39m     \u001b[38;5;66;03m# in Windows, when there is a postmaster.pid,  init_ctl seems to return\u001b[39;00m\n\u001b[32m    203\u001b[39m     \u001b[38;5;66;03m# but the file is not immediately updated, here we wait until the file shows\u001b[39;00m\n\u001b[32m    204\u001b[39m     \u001b[38;5;66;03m# a new running server. see test_stale_postmaster\u001b[39;00m\n\u001b[32m    205\u001b[39m     _logger.info(\u001b[33mf\u001b[39m\u001b[33m'\u001b[39m\u001b[33mwaiting for postmaster info to show a running process\u001b[39m\u001b[33m'\u001b[39m)\n",
      "\u001b[36mFile \u001b[39m\u001b[32mc:\\Dev\\PPS\\env\\Lib\\site-packages\\pixeltable_pgserver\\postgres_server.py:189\u001b[39m, in \u001b[36mPostgresServer.ensure_postgres_running\u001b[39m\u001b[34m(self)\u001b[39m\n\u001b[32m    187\u001b[39m \u001b[38;5;28;01mtry\u001b[39;00m:\n\u001b[32m    188\u001b[39m     _logger.info(\u001b[33mf\u001b[39m\u001b[33m'\u001b[39m\u001b[33mrunning pg_ctl... \u001b[39m\u001b[38;5;132;01m{\u001b[39;00mpg_ctl_args\u001b[38;5;132;01m=}\u001b[39;00m\u001b[33m'\u001b[39m)\n\u001b[32m--> \u001b[39m\u001b[32m189\u001b[39m     \u001b[43mpg_ctl\u001b[49m\u001b[43m(\u001b[49m\u001b[43mpg_ctl_args\u001b[49m\u001b[43m,\u001b[49m\u001b[43m \u001b[49m\u001b[43mpgdata\u001b[49m\u001b[43m=\u001b[49m\u001b[38;5;28;43mself\u001b[39;49m\u001b[43m.\u001b[49m\u001b[43mpgdata\u001b[49m\u001b[43m,\u001b[49m\u001b[43m \u001b[49m\u001b[43muser\u001b[49m\u001b[43m=\u001b[49m\u001b[38;5;28;43mself\u001b[39;49m\u001b[43m.\u001b[49m\u001b[43msystem_user\u001b[49m\u001b[43m,\u001b[49m\u001b[43m \u001b[49m\u001b[43mtimeout\u001b[49m\u001b[43m=\u001b[49m\u001b[32;43m10\u001b[39;49m\u001b[43m)\u001b[49m\n\u001b[32m    190\u001b[39m \u001b[38;5;28;01mexcept\u001b[39;00m subprocess.CalledProcessError \u001b[38;5;28;01mas\u001b[39;00m err:\n\u001b[32m    191\u001b[39m     _logger.error(\n\u001b[32m    192\u001b[39m         \u001b[33mf\u001b[39m\u001b[33m'\u001b[39m\u001b[33mFailed to start server.\u001b[39m\u001b[38;5;130;01m\\n\u001b[39;00m\u001b[33mShowing contents of postgres server log (\u001b[39m\u001b[38;5;132;01m{\u001b[39;00m\u001b[38;5;28mself\u001b[39m.log.absolute()\u001b[38;5;132;01m}\u001b[39;00m\u001b[33m) below:\u001b[39m\u001b[38;5;130;01m\\n\u001b[39;00m\u001b[38;5;132;01m{\u001b[39;00m\u001b[38;5;28mself\u001b[39m.log.read_text()\u001b[38;5;132;01m}\u001b[39;00m\u001b[33m'\u001b[39m\n\u001b[32m    193\u001b[39m     )\n",
      "\u001b[36mFile \u001b[39m\u001b[32mc:\\Dev\\PPS\\env\\Lib\\site-packages\\pixeltable_pgserver\\_commands.py:41\u001b[39m, in \u001b[36mcreate_command_function.<locals>.command\u001b[39m\u001b[34m(args, pgdata, **kwargs)\u001b[39m\n\u001b[32m     37\u001b[39m _logger.info(\u001b[33m'\u001b[39m\u001b[33mRunning commandline:\u001b[39m\u001b[38;5;130;01m\\n\u001b[39;00m\u001b[38;5;132;01m%s\u001b[39;00m\u001b[38;5;130;01m\\n\u001b[39;00m\u001b[33mwith kwargs: `\u001b[39m\u001b[38;5;132;01m%s\u001b[39;00m\u001b[33m`\u001b[39m\u001b[33m'\u001b[39m, full_command_line, kwargs)\n\u001b[32m     38\u001b[39m \u001b[38;5;66;03m# NB: capture_output=True, as well as using stdout=subprocess.PIPE and stderr=subprocess.PIPE\u001b[39;00m\n\u001b[32m     39\u001b[39m \u001b[38;5;66;03m# can cause this call to hang, even with a time-out depending on the command, (pg_ctl)\u001b[39;00m\n\u001b[32m     40\u001b[39m \u001b[38;5;66;03m# so we use two temporary files instead\u001b[39;00m\n\u001b[32m---> \u001b[39m\u001b[32m41\u001b[39m result = \u001b[43msubprocess\u001b[49m\u001b[43m.\u001b[49m\u001b[43mrun\u001b[49m\u001b[43m(\u001b[49m\n\u001b[32m     42\u001b[39m \u001b[43m    \u001b[49m\u001b[43mfull_command_line\u001b[49m\u001b[43m,\u001b[49m\u001b[43m \u001b[49m\u001b[43mcheck\u001b[49m\u001b[43m=\u001b[49m\u001b[38;5;28;43;01mTrue\u001b[39;49;00m\u001b[43m,\u001b[49m\u001b[43m \u001b[49m\u001b[43mstdout\u001b[49m\u001b[43m=\u001b[49m\u001b[43mstdout\u001b[49m\u001b[43m,\u001b[49m\u001b[43m \u001b[49m\u001b[43mstderr\u001b[49m\u001b[43m=\u001b[49m\u001b[43mstderr\u001b[49m\u001b[43m,\u001b[49m\u001b[43m \u001b[49m\u001b[43mtext\u001b[49m\u001b[43m=\u001b[49m\u001b[38;5;28;43;01mTrue\u001b[39;49;00m\u001b[43m,\u001b[49m\u001b[43m \u001b[49m\u001b[43m*\u001b[49m\u001b[43m*\u001b[49m\u001b[43mkwargs\u001b[49m\n\u001b[32m     43\u001b[39m \u001b[43m\u001b[49m\u001b[43m)\u001b[49m\n\u001b[32m     44\u001b[39m stdout.seek(\u001b[32m0\u001b[39m)\n\u001b[32m     45\u001b[39m stderr.seek(\u001b[32m0\u001b[39m)\n",
      "\u001b[36mFile \u001b[39m\u001b[32m~\\AppData\\Local\\Programs\\Python\\Python312\\Lib\\subprocess.py:550\u001b[39m, in \u001b[36mrun\u001b[39m\u001b[34m(input, capture_output, timeout, check, *popenargs, **kwargs)\u001b[39m\n\u001b[32m    548\u001b[39m \u001b[38;5;28;01mwith\u001b[39;00m Popen(*popenargs, **kwargs) \u001b[38;5;28;01mas\u001b[39;00m process:\n\u001b[32m    549\u001b[39m     \u001b[38;5;28;01mtry\u001b[39;00m:\n\u001b[32m--> \u001b[39m\u001b[32m550\u001b[39m         stdout, stderr = \u001b[43mprocess\u001b[49m\u001b[43m.\u001b[49m\u001b[43mcommunicate\u001b[49m\u001b[43m(\u001b[49m\u001b[38;5;28;43minput\u001b[39;49m\u001b[43m,\u001b[49m\u001b[43m \u001b[49m\u001b[43mtimeout\u001b[49m\u001b[43m=\u001b[49m\u001b[43mtimeout\u001b[49m\u001b[43m)\u001b[49m\n\u001b[32m    551\u001b[39m     \u001b[38;5;28;01mexcept\u001b[39;00m TimeoutExpired \u001b[38;5;28;01mas\u001b[39;00m exc:\n\u001b[32m    552\u001b[39m         process.kill()\n",
      "\u001b[36mFile \u001b[39m\u001b[32m~\\AppData\\Local\\Programs\\Python\\Python312\\Lib\\subprocess.py:1228\u001b[39m, in \u001b[36mPopen.communicate\u001b[39m\u001b[34m(self, input, timeout)\u001b[39m\n\u001b[32m   1225\u001b[39m     \u001b[38;5;28;01mfinally\u001b[39;00m:\n\u001b[32m   1226\u001b[39m         \u001b[38;5;28mself\u001b[39m._communication_started = \u001b[38;5;28;01mTrue\u001b[39;00m\n\u001b[32m-> \u001b[39m\u001b[32m1228\u001b[39m     sts = \u001b[38;5;28;43mself\u001b[39;49m\u001b[43m.\u001b[49m\u001b[43mwait\u001b[49m\u001b[43m(\u001b[49m\u001b[43mtimeout\u001b[49m\u001b[43m=\u001b[49m\u001b[38;5;28;43mself\u001b[39;49m\u001b[43m.\u001b[49m\u001b[43m_remaining_time\u001b[49m\u001b[43m(\u001b[49m\u001b[43mendtime\u001b[49m\u001b[43m)\u001b[49m\u001b[43m)\u001b[49m\n\u001b[32m   1230\u001b[39m \u001b[38;5;28;01mreturn\u001b[39;00m (stdout, stderr)\n",
      "\u001b[36mFile \u001b[39m\u001b[32m~\\AppData\\Local\\Programs\\Python\\Python312\\Lib\\subprocess.py:1264\u001b[39m, in \u001b[36mPopen.wait\u001b[39m\u001b[34m(self, timeout)\u001b[39m\n\u001b[32m   1262\u001b[39m     endtime = _time() + timeout\n\u001b[32m   1263\u001b[39m \u001b[38;5;28;01mtry\u001b[39;00m:\n\u001b[32m-> \u001b[39m\u001b[32m1264\u001b[39m     \u001b[38;5;28;01mreturn\u001b[39;00m \u001b[38;5;28;43mself\u001b[39;49m\u001b[43m.\u001b[49m\u001b[43m_wait\u001b[49m\u001b[43m(\u001b[49m\u001b[43mtimeout\u001b[49m\u001b[43m=\u001b[49m\u001b[43mtimeout\u001b[49m\u001b[43m)\u001b[49m\n\u001b[32m   1265\u001b[39m \u001b[38;5;28;01mexcept\u001b[39;00m \u001b[38;5;167;01mKeyboardInterrupt\u001b[39;00m:\n\u001b[32m   1266\u001b[39m     \u001b[38;5;66;03m# https://bugs.python.org/issue25942\u001b[39;00m\n\u001b[32m   1267\u001b[39m     \u001b[38;5;66;03m# The first keyboard interrupt waits briefly for the child to\u001b[39;00m\n\u001b[32m   1268\u001b[39m     \u001b[38;5;66;03m# exit under the common assumption that it also received the ^C\u001b[39;00m\n\u001b[32m   1269\u001b[39m     \u001b[38;5;66;03m# generated SIGINT and will exit rapidly.\u001b[39;00m\n\u001b[32m   1270\u001b[39m     \u001b[38;5;28;01mif\u001b[39;00m timeout \u001b[38;5;129;01mis\u001b[39;00m \u001b[38;5;129;01mnot\u001b[39;00m \u001b[38;5;28;01mNone\u001b[39;00m:\n",
      "\u001b[36mFile \u001b[39m\u001b[32m~\\AppData\\Local\\Programs\\Python\\Python312\\Lib\\subprocess.py:1593\u001b[39m, in \u001b[36mPopen._wait\u001b[39m\u001b[34m(self, timeout)\u001b[39m\n\u001b[32m   1590\u001b[39m     result = _winapi.WaitForSingleObject(\u001b[38;5;28mself\u001b[39m._handle,\n\u001b[32m   1591\u001b[39m                                          timeout_millis)\n\u001b[32m   1592\u001b[39m     \u001b[38;5;28;01mif\u001b[39;00m result == _winapi.WAIT_TIMEOUT:\n\u001b[32m-> \u001b[39m\u001b[32m1593\u001b[39m         \u001b[38;5;28;01mraise\u001b[39;00m TimeoutExpired(\u001b[38;5;28mself\u001b[39m.args, timeout)\n\u001b[32m   1594\u001b[39m     \u001b[38;5;28mself\u001b[39m.returncode = _winapi.GetExitCodeProcess(\u001b[38;5;28mself\u001b[39m._handle)\n\u001b[32m   1595\u001b[39m \u001b[38;5;28;01mreturn\u001b[39;00m \u001b[38;5;28mself\u001b[39m.returncode\n",
      "\u001b[31mTimeoutExpired\u001b[39m: Command '['c:\\\\Dev\\\\PPS\\\\env\\\\Lib\\\\site-packages\\\\pixeltable_pgserver\\\\pginstall\\\\bin\\\\pg_ctl.exe', '-D', 'C:\\\\Users\\\\mateo\\\\.pixeltable\\\\pgdata', '-w', '-o', '-h \"127.0.0.1\"', '-o', '-p 53481', '-l', 'C:\\\\Users\\\\mateo\\\\.pixeltable\\\\pgdata\\\\log', 'start']' timed out after 10.0 seconds"
     ]
    }
   ],
   "source": [
    "# Inicializa el procesador de imágenes\n",
    "image_processor = ImageProcessor()\n",
    "image_processor.setup_processing(extract_text=True, enable_search=True)\n",
    "\n",
    "print(\"Setup terminado\")"
   ]
  },
  {
   "cell_type": "code",
   "execution_count": null,
   "metadata": {},
   "outputs": [],
   "source": [
    "# Búsqueda con la query de texto\n",
    "print(f\"Searching for images matching text: '{search_query}'\")\n",
    "text_search_results = image_processor.search(\"Text\", text_query=search_query)\n",
    "print(f\"Found {len(text_search_results)} matching images\")\n",
    "\n",
    "# Muestra resultados\n",
    "for i, result in enumerate(text_search_results[:3]):\n",
    "    display(result.image)\n",
    "    print(f\"Result {i+1}:\")\n",
    "    if hasattr(result, 'license_plate_text') and result.license_plate_text:\n",
    "        print(f\"License plate text: {result.license_plate_text}\")"
   ]
  },
  {
   "cell_type": "code",
   "execution_count": null,
   "metadata": {},
   "outputs": [],
   "source": [
    "# Búsqueda con la image query\n",
    "if os.path.exists(search_image_path):\n",
    "    query_image = PIL.Image.open(search_image_path)\n",
    "    print(f\"Searching for images similar to: {os.path.basename(search_image_path)}\")\n",
    "    display(query_image)\n",
    "    \n",
    "    image_search_results = image_processor.search(\"Image\", image_query=query_image)\n",
    "    print(f\"Found {len(image_search_results)} similar images\")\n",
    "    \n",
    "    # muestra resultados\n",
    "    for i, result in enumerate(image_search_results[:3]):\n",
    "        display(result.image)\n",
    "        print(f\"Result {i+1}:\")\n",
    "        if hasattr(result, 'license_plate_text') and result.license_plate_text:\n",
    "            print(f\"License plate text: {result.license_plate_text}\")\n",
    "else:\n",
    "    print(f\"Query image not found at: {search_image_path}\")"
   ]
  },
  {
   "cell_type": "markdown",
   "metadata": {},
   "source": [
    "## Video Processing\n",
    "\n",
    "Process videos from the specified directory using the VideoProcessor."
   ]
  },
  {
   "cell_type": "code",
   "execution_count": null,
   "metadata": {},
   "outputs": [],
   "source": [
    "# List de videos disponibles\n",
    "video_files = glob.glob(os.path.join(videos_directory, \"*.*\"))\n",
    "print(f\"Found {len(video_files)} videos in {videos_directory}\")\n",
    "for vid in video_files[:5]:  \n",
    "    print(f\" - {os.path.basename(vid)}\")\n",
    "if len(video_files) > 5:\n",
    "    print(f\" ... and {len(video_files) - 5} more\")"
   ]
  },
  {
   "cell_type": "code",
   "execution_count": null,
   "metadata": {},
   "outputs": [],
   "source": [
    "# Inicializa el procesador de videos\n",
    "video_processor = VideoProcessor()\n",
    "video_processor.setup_processing(extract_text=True, enable_search=True)\n",
    "\n",
    "print(\"Procesamiento hecho\")"
   ]
  },
  {
   "cell_type": "code",
   "execution_count": null,
   "metadata": {},
   "outputs": [],
   "source": [
    "# Prueba con text query\n",
    "print(f\"Searching for video frames matching text: '{search_query}'\")\n",
    "video_text_results = video_processor.search(\"Text\", text_query=search_query)\n",
    "print(f\"Found {len(video_text_results)} matching frames\")\n",
    "\n",
    "# Muestra resultados\n",
    "for i, result in enumerate(video_text_results[:3]):\n",
    "    display(result.frame)\n",
    "    print(f\"Result {i+1} from video position: {result.pos:.2f}s\")\n",
    "    if hasattr(result, 'license_plate_text') and result.license_plate_text:\n",
    "        print(f\"License plate text: {result.license_plate_text}\")"
   ]
  },
  {
   "cell_type": "code",
   "execution_count": null,
   "metadata": {},
   "outputs": [],
   "source": [
    "# Prueba con image query\n",
    "if os.path.exists(search_image_path):\n",
    "    query_image = PIL.Image.open(search_image_path)\n",
    "    print(f\"Searching for video frames similar to: {os.path.basename(search_image_path)}\")\n",
    "    display(query_image)\n",
    "    \n",
    "    video_image_results = video_processor.search(\"Image\", image_query=query_image)\n",
    "    print(f\"Found {len(video_image_results)} similar frames\")\n",
    "    \n",
    "    # muestra resultados\n",
    "    for i, result in enumerate(video_image_results[:3]):\n",
    "        display(result.frame)\n",
    "        print(f\"Result {i+1} from video position: {result.pos:.2f}s\")\n",
    "        if hasattr(result, 'license_plate_text') and result.license_plate_text:\n",
    "            print(f\"License plate text: {result.license_plate_text}\")\n",
    "else:\n",
    "    print(f\"Query image not found at: {search_image_path}\")"
   ]
  }
 ],
 "metadata": {
  "kernelspec": {
   "display_name": "env",
   "language": "python",
   "name": "python3"
  },
  "language_info": {
   "codemirror_mode": {
    "name": "ipython",
    "version": 3
   },
   "file_extension": ".py",
   "mimetype": "text/x-python",
   "name": "python",
   "nbconvert_exporter": "python",
   "pygments_lexer": "ipython3",
   "version": "3.12.5"
  }
 },
 "nbformat": 4,
 "nbformat_minor": 4
}
